<?xml version="1.0" encoding="utf-8"?>
<robot
  name="4axis_robot">
  <link
    name="base_link">
    <inertial>
      <origin
        xyz="-0.0819771145953124 -0.0394328123681596 -0.0605612328464758"
        rpy="0 0 0" />
      <mass
        value="7.43807257011137" />
      <inertia
        ixx="0.33173827700719"
        ixy="-1.9135079863359E-05"
        ixz="-2.38586363043419E-05"
        iyy="0.51093790700966"
        iyz="1.14706407748212E-05"
        izz="0.661072726327959" />
    </inertial>
    <visual>
      <origin
        xyz="0 0 0"
        rpy="0 0 0" />
      <geometry>
        <mesh
          filename="package://cpp06_urdf/meshes/base_link.STL" />
      </geometry>
      <material
        name="">
        <color
          rgba="0.792156862745098 0.819607843137255 0.933333333333333 1" />
      </material>
    </visual>
    <collision>
      <origin
        xyz="0 0 0"
        rpy="0 0 0" />
      <geometry>
        <mesh
          filename="package://cpp06_urdf/meshes/base_link.STL" />
      </geometry>
    </collision>
  </link>
  <link
    name="Link1">
    <inertial>
      <origin
        xyz="-0.181408083975973 0.0581405834318814 -0.00954482706978561"
        rpy="0 0 0" />
      <mass
        value="21.8220304142984" />
      <inertia
        ixx="0.504636458557709"
        ixy="0.155628988709401"
        ixz="-0.0329547833491183"
        iyy="0.553116042516836"
        iyz="0.0317725740787119"
        izz="0.679054189085337" />
    </inertial>
    <visual>
      <origin
        xyz="0 0 0"
        rpy="0 0 0" />
      <geometry>
        <mesh
          filename="package://cpp06_urdf/meshes/Link1.STL" />
      </geometry>
      <material
        name="">
        <color
          rgba="0.792156862745098 0.819607843137255 0.933333333333333 1" />
      </material>
    </visual>
    <collision>
      <origin
        xyz="0 0 0"
        rpy="0 0 0" />
      <geometry>
        <mesh
          filename="package://cpp06_urdf/meshes/Link1.STL" />
      </geometry>
    </collision>
  </link>
  <joint
    name="Joint1"
    type="revolute">
    <origin
      xyz="-0.081947 -0.039447 0.12191"
      rpy="0.031307 1.5708 0" />
    <parent
      link="base_link" />
    <child
      link="Link1" />
    <axis
      xyz="-1 0 0" />
    <limit
      lower="-3.14"
      upper="3.14"
      effort="100"
      velocity="1" />
  </joint>
  <link
    name="Link2">
    <inertial>
      <origin
        xyz="0.00711588212779668 0.430462624171802 -0.181072168675245"
        rpy="0 0 0" />
      <mass
        value="30.611698680693" />
      <inertia
        ixx="2.84056184663837"
        ixy="0.00176708532036297"
        ixz="-0.000605585595495953"
        iyy="0.803420570623051"
        iyz="0.881921717620968"
        izz="2.25142106377957" />
    </inertial>
    <visual>
      <origin
        xyz="0 0 0"
        rpy="0 0 0" />
      <geometry>
        <mesh
          filename="package://cpp06_urdf/meshes/Link2.STL" />
      </geometry>
      <material
        name="">
        <color
          rgba="0.792156862745098 0.819607843137255 0.933333333333333 1" />
      </material>
    </visual>
    <collision>
      <origin
        xyz="0 0 0"
        rpy="0 0 0" />
      <geometry>
        <mesh
          filename="package://cpp06_urdf/meshes/Link2.STL" />
      </geometry>
    </collision>
  </link>
  <joint
    name="Joint2"
    type="revolute">
    <origin
      xyz="-0.34141 0.21122 0.232"
      rpy="2.3823 1.5708 2.9781" />
    <parent
      link="Link1" />
    <child
      link="Link2" />
    <axis
      xyz="-1 0 0" />
    <limit
      lower="-3.14"
      upper="3.14"
      effort="100"
      velocity="1" />
  </joint>
  <link
    name="Link3">
    <inertial>
      <origin
        xyz="0.0011288679773169 0.0366346901842278 0.317203297355097"
        rpy="0 0 0" />
      <mass
        value="32.1927283247081" />
      <inertia
        ixx="4.01515992838776"
        ixy="0.00131937245345131"
        ixz="0.0113529681997448"
        iyy="3.86196322052592"
        iyz="-0.336440031503833"
        izz="0.399977912527002" />
    </inertial>
    <visual>
      <origin
        xyz="0 0 0"
        rpy="0 0 0" />
      <geometry>
        <mesh
          filename="package://cpp06_urdf/meshes/Link3.STL" />
      </geometry>
      <material
        name="">
        <color
          rgba="0.792156862745098 0.819607843137255 0.933333333333333 1" />
      </material>
    </visual>
    <collision>
      <origin
        xyz="0 0 0"
        rpy="0 0 0" />
      <geometry>
        <mesh
          filename="package://cpp06_urdf/meshes/Link3.STL" />
      </geometry>
    </collision>
  </link>
  <joint
    name="Joint3"
    type="revolute">
    <origin
      xyz="0.3765 0.82481 -0.49591"
      rpy="2.6936 0 0" />
    <parent
      link="Link2" />
    <child
      link="Link3" />
    <axis
      xyz="1 0 0" />
    <limit
      lower="-3.14"
      upper="3.14"
      effort="100"
      velocity="1" />
  </joint>
  <link
    name="Link4">
    <inertial>
      <origin
        xyz="0.16252 -0.21385 2.9168E-07"
        rpy="0 0 0" />
      <mass
        value="12.165" />
      <inertia
        ixx="0.28821"
        ixy="0.00080328"
        ixz="8.1167E-07"
        iyy="0.107"
        iyz="-1.4214E-07"
        izz="0.29515" />
    </inertial>
    <visual>
      <origin
        xyz="0 0 0"
        rpy="0 0 0" />
      <geometry>
        <mesh
          filename="package://cpp06_urdf/meshes/Link4.STL" />
      </geometry>
      <material
        name="">
        <color
          rgba="0.79216 0.81961 0.93333 1" />
      </material>
    </visual>
    <collision>
      <origin
        xyz="0 0 0"
        rpy="0 0 0" />
      <geometry>
        <mesh
          filename="package://cpp06_urdf/meshes/Link4.STL" />
      </geometry>
    </collision>
  </link>
  <joint
    name="Joint4"
    type="revolute">
    <origin
      xyz="0 0.070837 0.99728"
      rpy="0.7098 -1.5708 0" />
    <parent
      link="Link3" />
    <child
      link="Link4" />
    <axis
      xyz="1 0 0" />
    <limit
      lower="-3.14"
      upper="3.14"
      effort="100"
      velocity="1" />
  </joint>
</robot>