<!-- 
    练习：编写四轮差速机器人的底盘模型

    参数：
        长 0.2m
        宽 0.12m
        高 0.07m
        离地 0.015m
        车轮半径：0.025m
        车轮厚度：0.02m

 -->
 <robot name="exercise_demo">
    <!-- 定义颜色 -->
    <material name="yellow">
      <color rgba="0.7 0.7 0 0.8" />
    </material>
    <material name="red">
      <color rgba="0.8 0.1 0.1 0.8" />
    </material>
    <material name="gray">
      <color rgba="0.2 0.2 0.2 0.8" />
    </material>
  
    <link name="base_footprint">
      <visual>
        <geometry>
            <sphere radius="0.001"/>
        </geometry>
      </visual>
    </link>
    <!-- 车体 -->
    <link name="base_link">
      <visual>
          <!-- 形状 -->
          <geometry>
              <box size="0.2 0.12 0.07" />
          </geometry>
          <origin xyz="0 0 0" rpy="0 0 0" />
          <material name="yellow"/>
      </visual>
    </link>
  
    <joint name="baselink2basefootprint" type="fixed">
      <parent link="base_footprint"/>
      <child link="base_link"/>
      <origin xyz="0.0 0.0 0.05"/>
    </joint>
  
    <!-- ==============车轮================= -->
    <!-- 左前轮 -->
    <link name="front_left_wheel">
        <visual>
            <geometry>
                <cylinder radius="0.025" length="0.02"/>
            </geometry>
            <origin xyz="0 0 0" rpy="1.57 0 0" />
            <material name="gray" />
        </visual>
    </link>
  
    <!-- 左前轮关节 -->
    <joint name="frontleftwheel2baselink" type="continuous">
        <parent link="base_link"/>
        <child link="front_left_wheel" />
        <!-- 需要计算两个 link 的物理中心之间的偏移量 -->
        <origin xyz="0.075 0.06 -0.025" rpy="0 0 0" />
        <axis xyz="0 1 0" />
    </joint>
  
    <!-- 右前轮 -->
    <link name="front_right_wheel">
      <visual>
          <geometry>
              <cylinder radius="0.025" length="0.02"/>
          </geometry>
          <origin xyz="0 0 0" rpy="1.57 0 0" />
          <material name="gray" />
      </visual>
    </link>
  
    <!-- 右前轮关节 -->
    <joint name="frontrightwheel2baselink" type="continuous">
        <parent link="base_link"/>
        <child link="front_right_wheel" />
        <!-- 需要计算两个 link 的物理中心之间的偏移量 -->
        <origin xyz="0.075 -0.06 -0.025" rpy="0 0 0" />
        <axis xyz="0 1 0" />
    </joint>
  
    <!-- 左后轮 -->
    <link name="back_left_wheel">
      <visual>
          <geometry>
              <cylinder radius="0.025" length="0.02"/>
          </geometry>
          <origin xyz="0 0 0" rpy="1.57 0 0" />
          <material name="gray" />
      </visual>
    </link>
  
    <!-- 左后轮关节 -->
    <joint name="backleftwheel2baselink" type="continuous">
      <parent link="base_link"/>
      <child link="back_left_wheel" />
      <!-- 需要计算两个 link 的物理中心之间的偏移量 -->
      <origin xyz="-0.075 0.06 -0.025" rpy="0 0 0" />
      <axis xyz="0 1 0" />
    </joint>
  
    <!-- 右后轮 -->
    <link name="back_right_wheel">
      <visual>
          <geometry>
              <cylinder radius="0.025" length="0.02"/>
          </geometry>
          <origin xyz="0 0 0" rpy="1.57 0 0" />
          <material name="gray" />
      </visual>
    </link>
  
    <!-- 右后轮关节 -->
    <joint name="backrightwheel2baselink" type="continuous">
      <parent link="base_link"/>
      <child link="back_right_wheel" />
      <!-- 需要计算两个 link 的物理中心之间的偏移量 -->
      <origin xyz="-0.075 -0.06 -0.025" rpy="0 0 0" />
      <axis xyz="0 1 0" />
    </joint>
  
  
  </robot>