<?xml version="1.0" ?>
<!-- =================================================================================== -->
<!-- |    This document was autogenerated by xacro from /home/tungchiahui/source/ROS2_WS/4.ws02_tools/install/cpp06_urdf/share/cpp06_urdf/urdf/xacro/car.urdf.xacro | -->
<!-- |    EDITING THIS FILE BY HAND IS NOT RECOMMENDED                                 | -->
<!-- =================================================================================== -->
<robot name="car">
  <!-- 定义颜色 -->
  <material name="yellow">
    <color rgba="0.7 0.7 0 0.8"/>
  </material>
  <material name="red">
    <color rgba="0.8 0.1 0.1 0.8"/>
  </material>
  <material name="gray">
    <color rgba="0.2 0.2 0.2 0.95"/>
  </material>
  <!-- 定义 base_footprint -->
  <link name="base_footprint">
    <visual>
      <geometry>
        <sphere radius="0.001"/>
      </geometry>
    </visual>
  </link>
  <!-- 定义 base_link -->
  <link name="base_link">
    <visual>
      <!-- 形状 -->
      <geometry>
        <box size="0.2 0.12 0.07"/>
      </geometry>
      <origin rpy="0 0 0" xyz="0 0 0"/>
      <material name="yellow"/>
    </visual>
  </link>
  <joint name="baselink2basefootprint" type="fixed">
    <parent link="base_footprint"/>
    <child link="base_link"/>
    <origin xyz="0.0 0.0 0.05"/>
  </joint>
  <link name="left_front_wheel">
    <visual>
      <geometry>
        <cylinder length="0.02" radius="0.025"/>
      </geometry>
      <origin rpy="1.5708 0 0" xyz="0 0 0"/>
      <material name="gray"/>
    </visual>
  </link>
  <joint name="left_front2baselink" type="continuous">
    <parent link="base_link"/>
    <child link="left_front_wheel"/>
    <origin rpy="0 0 0" xyz="0.07500000000000001 0.06 -0.025"/>
    <axis xyz="0 1 0"/>
  </joint>
  <link name="left_back_wheel">
    <visual>
      <geometry>
        <cylinder length="0.02" radius="0.025"/>
      </geometry>
      <origin rpy="1.5708 0 0" xyz="0 0 0"/>
      <material name="gray"/>
    </visual>
  </link>
  <joint name="left_back2baselink" type="continuous">
    <parent link="base_link"/>
    <child link="left_back_wheel"/>
    <origin rpy="0 0 0" xyz="-0.07500000000000001 0.06 -0.025"/>
    <axis xyz="0 1 0"/>
  </joint>
  <link name="right_front_wheel">
    <visual>
      <geometry>
        <cylinder length="0.02" radius="0.025"/>
      </geometry>
      <origin rpy="1.5708 0 0" xyz="0 0 0"/>
      <material name="gray"/>
    </visual>
  </link>
  <joint name="right_front2baselink" type="continuous">
    <parent link="base_link"/>
    <child link="right_front_wheel"/>
    <origin rpy="0 0 0" xyz="0.07500000000000001 -0.06 -0.025"/>
    <axis xyz="0 1 0"/>
  </joint>
  <link name="right_back_wheel">
    <visual>
      <geometry>
        <cylinder length="0.02" radius="0.025"/>
      </geometry>
      <origin rpy="1.5708 0 0" xyz="0 0 0"/>
      <material name="gray"/>
    </visual>
  </link>
  <joint name="right_back2baselink" type="continuous">
    <parent link="base_link"/>
    <child link="right_back_wheel"/>
    <origin rpy="0 0 0" xyz="-0.07500000000000001 -0.06 -0.025"/>
    <axis xyz="0 1 0"/>
  </joint>
  <!-- 摄像头安装的z坐标:底盘高度 / 2 + 摄像头高度 / 2  -->
  <!-- 摄像头关节以及link -->
  <link name="camera">
    <visual>
      <geometry>
        <box size="0.012 0.05 0.01"/>
      </geometry>
      <origin rpy="0.0 0.0 0.0" xyz="0.0 0.0 0.0"/>
      <material name="red"/>
    </visual>
  </link>
  <joint name="camera2baselink" type="fixed">
    <parent link="base_link"/>
    <child link="camera"/>
    <origin xyz="0.094 0.0 0.04"/>
  </joint>
  <material name="blue">
    <color rgba="0.0 0.0 0.4 0.95"/>
  </material>
  <!-- 雷达安装的z坐标:车体高度 / 2 + 雷达高度 / 2  -->
  <!-- 雷达关节以及link -->
  <link name="laser">
    <visual>
      <geometry>
        <cylinder length="0.03" radius="0.03"/>
      </geometry>
      <origin rpy="0.0 0.0 0.0" xyz="0.0 0.0 0.0"/>
      <material name="blue"/>
    </visual>
  </link>
  <joint name="laser2baselink" type="fixed">
    <parent link="base_link"/>
    <child link="laser"/>
    <origin xyz="0.0 0.0 0.05"/>
  </joint>
</robot>
