<?xml version="1.0" encoding="utf-8"?>
<robot
  name="fouraxisrobot_kine">
  <link
    name="base_link">
    <inertial>
      <origin
        xyz="2.7802E-36 0.012867 1.1428E-18"
        rpy="0 0 0" />
      <mass
        value="0.23562" />
      <inertia
        ixx="0.00017569"
        ixy="6.7763E-21"
        ixz="2.7105E-20"
        iyy="0.00031802"
        iyz="5.9354E-21"
        izz="0.00017569" />
    </inertial>
    <visual>
      <origin
        xyz="0 0 0"
        rpy="0 0 0" />
      <geometry>
        <mesh
          filename="package://cpp06_urdf/meshes/base_link.STL" />
      </geometry>
      <material
        name="">
        <color
          rgba="0.79216 0.81961 0.93333 1" />
      </material>
    </visual>
    <collision>
      <origin
        xyz="0 0 0"
        rpy="0 0 0" />
      <geometry>
        <mesh
          filename="package://cpp06_urdf/meshes/base_link.STL" />
      </geometry>
    </collision>
  </link>
  <link
    name="link1">
    <inertial>
      <origin
        xyz="0.065125 2.0116E-17 -2.2224E-17"
        rpy="0 0 0" />
      <mass
        value="0.39015" />
      <inertia
        ixx="0.00027739"
        ixy="8.0815E-20"
        ixz="8.0388E-20"
        iyy="0.00072264"
        iyz="2.7105E-20"
        izz="0.00087866" />
    </inertial>
    <visual>
      <origin
        xyz="0 0 0"
        rpy="0 0 0" />
      <geometry>
        <mesh
          filename="package://cpp06_urdf/meshes/link1.STL" />
      </geometry>
      <material
        name="">
        <color
          rgba="0.79216 0.81961 0.93333 1" />
      </material>
    </visual>
    <collision>
      <origin
        xyz="0 0 0"
        rpy="0 0 0" />
      <geometry>
        <mesh
          filename="package://cpp06_urdf/meshes/link1.STL" />
      </geometry>
    </collision>
  </link>
  <joint
    name="joint1"
    type="revolute">
    <origin
      xyz="0 0 0.03"
      rpy="0.4441 -1.5708 0" />
    <parent
      link="base_link" />
    <child
      link="link1" />
    <axis
      xyz="-1 0 0" />
    <limit
      lower="-3.14"
      upper="3.14"
      effort="100"
      velocity="1" />
  </joint>
  <link
    name="link2">
    <inertial>
      <origin
        xyz="0.18014 6.6787E-17 -1.5727E-16"
        rpy="0 0 0" />
      <mass
        value="0.99282" />
      <inertia
        ixx="0.00060396"
        ixy="-6.6331E-18"
        ixz="-1.6839E-18"
        iyy="0.014885"
        iyz="8.6736E-19"
        izz="0.015332" />
    </inertial>
    <visual>
      <origin
        xyz="0 0 0"
        rpy="0 0 0" />
      <geometry>
        <mesh
          filename="package://cpp06_urdf/meshes/link2.STL" />
      </geometry>
      <material
        name="">
        <color
          rgba="0.79216 0.81961 0.93333 1" />
      </material>
    </visual>
    <collision>
      <origin
        xyz="0 0 0"
        rpy="0 0 0" />
      <geometry>
        <mesh
          filename="package://cpp06_urdf/meshes/link2.STL" />
      </geometry>
    </collision>
  </link>
  <joint
    name="joint2"
    type="revolute">
    <origin
      xyz="0.14 0 0"
      rpy="-3.1416 0 0.02851" />
    <parent
      link="link1" />
    <child
      link="link2" />
    <axis
      xyz="0 0 -1" />
    <limit
      lower="-3.14"
      upper="3.14"
      effort="100"
      velocity="1" />
  </joint>
  <link
    name="link3">
    <inertial>
      <origin
        xyz="0.0720662695405814 -1.11022302462516E-16 3.85108611666851E-16"
        rpy="0 0 0" />
      <mass
        value="0.312359863114213" />
      <inertia
        ixx="0.000175816316923738"
        ixy="6.4205097401876E-19"
        ixz="2.03287907341032E-19"
        iyy="0.00121702131601706"
        iyz="-2.03287907341032E-20"
        izz="0.0013696334055072" />
    </inertial>
    <visual>
      <origin
        xyz="0 0 0"
        rpy="0 0 0" />
      <geometry>
        <mesh
          filename="package://cpp06_urdf/meshes/link3.STL" />
      </geometry>
      <material
        name="">
        <color
          rgba="0.792156862745098 0.819607843137255 0.933333333333333 1" />
      </material>
    </visual>
    <collision>
      <origin
        xyz="0 0 0"
        rpy="0 0 0" />
      <geometry>
        <mesh
          filename="package://cpp06_urdf/meshes/link3.STL" />
      </geometry>
    </collision>
  </link>
  <joint
    name="joint3"
    type="revolute">
    <origin
      xyz="0.4 0 0"
      rpy="0 0 1.494" />
    <parent
      link="link2" />
    <child
      link="link3" />
    <axis
      xyz="0 0 -1" />
    <limit
      lower="-3.14"
      upper="3.14"
      effort="100"
      velocity="1" />
  </joint>
  <link
    name="link4">
    <inertial>
      <origin
        xyz="-0.165854197997763 0 2.77555756156289E-16"
        rpy="0 0 0" />
      <mass
        value="0.309991148575129" />
      <inertia
        ixx="0.000166157816246607"
        ixy="1.09097843606354E-18"
        ixz="-2.57498015965307E-18"
        iyy="0.00392704064985496"
        iyz="5.42101086242752E-20"
        izz="0.00408803194695865" />
    </inertial>
    <visual>
      <origin
        xyz="0 0 0"
        rpy="0 0 0" />
      <geometry>
        <mesh
          filename="package://cpp06_urdf/meshes/link4.STL" />
      </geometry>
      <material
        name="">
        <color
          rgba="0.792156862745098 0.819607843137255 0.933333333333333 1" />
      </material>
    </visual>
    <collision>
      <origin
        xyz="0 0 0"
        rpy="0 0 0" />
      <geometry>
        <mesh
          filename="package://cpp06_urdf/meshes/link4.STL" />
      </geometry>
    </collision>
  </link>
  <joint
    name="joint4"
    type="revolute">
    <origin
      xyz="0.17 0 0"
      rpy="0 0 -2.4139" />
    <parent
      link="link3" />
    <child
      link="link4" />
    <axis
      xyz="0 0 -1" />
    <limit
      lower="-3.14"
      upper="3.14"
      effort="100"
      velocity="1" />
  </joint>
</robot>