<?xml version="1.0" encoding="utf-8"?>
<robot
  name="CyberNaviRobot">
  <link
    name="base_link">
    <inertial>
      <origin
        xyz="-0.0126930979005275 0.00191328701604972 0.138027242309266"
        rpy="0 0 0" />
      <mass
        value="1.02316767990512" />
      <inertia
        ixx="0.00139586884914313"
        ixy="-1.1634425915606E-06"
        ixz="2.08900696909113E-08"
        iyy="0.00163816424060367"
        iyz="1.3906877128818E-07"
        izz="0.00212627787861002" />
    </inertial>
    <visual>
      <origin
        xyz="-0.14 -0.0925 0"
        rpy="0 0 0" />
      <geometry>
        <mesh
          filename="package://mycar_description/meshes/base_link.STL" />
      </geometry>
      <material
        name="">
        <color
          rgba="1 1 1 1" />
      </material>
    </visual>
    <collision>
      <origin
        xyz="0 0 0"
        rpy="0 0 0" />
      <geometry>
        <mesh
          filename="package://mycar_description/meshes/base_link.STL" />
      </geometry>
    </collision>
  </link>
  <link
    name="left_front_wheel_link">
    <inertial>
      <origin
        xyz="-3.0979511909876E-06 0.0173322020637727 4.43766253017258E-06"
        rpy="0 0 0" />
      <mass
        value="0.0503853041294886" />
      <inertia
        ixx="5.77203859894131E-06"
        ixy="-6.39490308551869E-10"
        ixz="-6.55101507497994E-10"
        iyy="7.74120907350755E-06"
        iyz="1.14467480632514E-09"
        izz="5.77288622221224E-06" />
    </inertial>
    <visual>
      <origin
        xyz="0 0 0"
        rpy="0 0 0" />
      <geometry>
        <mesh
          filename="package://mycar_description/meshes/left_front_wheel_link.STL" />
      </geometry>
      <material
        name="">
        <color
          rgba="1 1 1 1" />
      </material>
    </visual>
    <collision>
      <origin
        xyz="0 0 0"
        rpy="0 0 0" />
      <geometry>
        <mesh
          filename="package://mycar_description/meshes/left_front_wheel_link.STL" />
      </geometry>
    </collision>
  </link>
  <joint
    name="left_front_wheel_joint"
    type="continuous">
    <origin
      xyz="0.094976 0.076703 0.038001"
      rpy="0 0 0" />
    <parent
      link="base_link" />
    <child
      link="left_front_wheel_link" />
    <axis
      xyz="0 1 0" />
  </joint>
  <link
    name="left_rear_wheel_link">
    <inertial>
      <origin
        xyz="-3.06188346035907E-06 0.017331873242395 -5.84140984641324E-06"
        rpy="0 0 0" />
      <mass
        value="0.0503852022031433" />
      <inertia
        ixx="5.7719914844331E-06"
        ixy="-6.47591418647473E-10"
        ixz="6.3996728285628E-10"
        iyy="7.74122667602425E-06"
        iyz="-1.13209672720901E-09"
        izz="5.77285855433357E-06" />
    </inertial>
    <visual>
      <origin
        xyz="0 0 0"
        rpy="0 0 0" />
      <geometry>
        <mesh
          filename="package://mycar_description/meshes/left_rear_wheel_link.STL" />
      </geometry>
      <material
        name="">
        <color
          rgba="1 1 1 1" />
      </material>
    </visual>
    <collision>
      <origin
        xyz="0 0 0"
        rpy="0 0 0" />
      <geometry>
        <mesh
          filename="package://mycar_description/meshes/left_rear_wheel_link.STL" />
      </geometry>
    </collision>
  </link>
  <joint
    name="left_rear_wheel_joint"
    type="continuous">
    <origin
      xyz="-0.078024 0.076703 0.038001"
      rpy="0 0 0" />
    <parent
      link="base_link" />
    <child
      link="left_rear_wheel_link" />
    <axis
      xyz="0 1 0" />
  </joint>
  <link
    name="right_front_wheel_link">
    <inertial>
      <origin
        xyz="3.06240360546661E-06 -0.0173318735620233 -5.84117647387666E-06"
        rpy="0 0 0" />
      <mass
        value="0.0503852021760132" />
      <inertia
        ixx="5.77199099297903E-06"
        ixy="-6.47832070333766E-10"
        ixz="-6.39570296767498E-10"
        iyy="7.74122684098967E-06"
        iyz="1.13229861557678E-09"
        izz="5.7728593340892E-06" />
    </inertial>
    <visual>
      <origin
        xyz="0 0 0"
        rpy="0 0 0" />
      <geometry>
        <mesh
          filename="package://mycar_description/meshes/right_front_wheel_link.STL" />
      </geometry>
      <material
        name="">
        <color
          rgba="1 1 1 1" />
      </material>
    </visual>
    <collision>
      <origin
        xyz="0 0 0"
        rpy="0 0 0" />
      <geometry>
        <mesh
          filename="package://mycar_description/meshes/right_front_wheel_link.STL" />
      </geometry>
    </collision>
  </link>
  <joint
    name="right_front_wheel_joint"
    type="continuous">
    <origin
      xyz="0.094976 -0.075297 0.038001"
      rpy="0 0 0" />
    <parent
      link="base_link" />
    <child
      link="right_front_wheel_link" />
    <axis
      xyz="0 1 0" />
  </joint>
  <link
    name="right_rear_wheel_link">
    <inertial>
      <origin
        xyz="3.09795119093903E-06 -0.0173322020637727 4.43766253057504E-06"
        rpy="0 0 0" />
      <mass
        value="0.0503853041294886" />
      <inertia
        ixx="5.77203859894127E-06"
        ixy="-6.39490308545873E-10"
        ixz="6.55101507484353E-10"
        iyy="7.7412090735075E-06"
        iyz="-1.14467480634659E-09"
        izz="5.77288622221223E-06" />
    </inertial>
    <visual>
      <origin
        xyz="0 0 0"
        rpy="0 0 0" />
      <geometry>
        <mesh
          filename="package://mycar_description/meshes/right_rear_wheel_link.STL" />
      </geometry>
      <material
        name="">
        <color
          rgba="1 1 1 1" />
      </material>
    </visual>
    <collision>
      <origin
        xyz="0 0 0"
        rpy="0 0 0" />
      <geometry>
        <mesh
          filename="package://mycar_description/meshes/right_rear_wheel_link.STL" />
      </geometry>
    </collision>
  </link>
  <joint
    name="right_rear_wheel_joint"
    type="continuous">
    <origin
      xyz="-0.078024 -0.075297 0.038001"
      rpy="0 0 0" />
    <parent
      link="base_link" />
    <child
      link="right_rear_wheel_link" />
    <axis
      xyz="0 1 0" />
  </joint>

<!-- 运动控制插件 -->
<gazebo>
    <plugin
        filename="ignition-gazebo-diff-drive-system"
        name="ignition::gazebo::systems::DiffDrive">
        <left_joint>left_front_wheel_joint</left_joint>
        <left_joint>left_rear_wheel_joint</left_joint>
        <right_joint>right_front_wheel_joint</right_joint>
        <right_joint>right_rear_wheel_joint</right_joint>
        <wheel_separation>0.4</wheel_separation>
        <wheel_radius>0.0415</wheel_radius>
        <odom_publish_frequency>50</odom_publish_frequency>
        <frame_id>odom</frame_id>
        <child_frame_id>base_link</child_frame_id>
        <topic>/cmd_vel</topic>
        <max_linear_acceleration>10</max_linear_acceleration>
        <min_linear_acceleration>-10</min_linear_acceleration>
        <max_angular_acceleration>10</max_angular_acceleration>
        <min_angular_acceleration>-10</min_angular_acceleration>
        <max_linear_velocity>0.5</max_linear_velocity>
        <min_linear_velocity>-0.5</min_linear_velocity>
        <max_angular_velocity>1</max_angular_velocity>
        <min_angular_velocity>-1</min_angular_velocity>
      </plugin>
  </gazebo>
  <!-- 关节状态发布 -->
  <gazebo>
    <plugin filename="ignition-gazebo-joint-state-publisher-system"
      name="ignition::gazebo::systems::JointStatePublisher">
    </plugin>
  </gazebo>



  <!-- 添加传感器插件 -->

<gazebo>
    <plugin
      filename="ignition-gazebo-sensors-system"
      name="ignition::gazebo::systems::Sensors">
      <render_engine>ogre2</render_engine>
    </plugin>
  </gazebo>

 <!-- 雷达传感器 -->
  <gazebo reference="laser">
    <sensor name='gpu_lidar' type='gpu_lidar'>
      <topic>scan</topic>
      <update_rate>30</update_rate>
      <lidar>
        <scan>
          <horizontal>
            <samples>640</samples>
            <resolution>1</resolution>
            <min_angle>-3.1415926</min_angle>
            <max_angle>3.1415926</max_angle>
          </horizontal>
          <vertical>
            <samples>16</samples>
            <resolution>1</resolution>
            <min_angle>-0.261799</min_angle>
            <max_angle>0.261799</max_angle>
          </vertical>
        </scan>
        <range>
          <min>0.08</min>
          <max>10.0</max>
          <resolution>0.01</resolution>
        </range>
      </lidar>
      <alwaysOn>1</alwaysOn>
      <visualize>true</visualize>
      <ignition_frame_id>base_link</ignition_frame_id>
    </sensor>
  </gazebo>

  <!-- 单目相机 -->

  <gazebo reference="camera" >
    <sensor name="cam_link" type="camera">
      <update_rate>10.0</update_rate>
      <always_on>true</always_on>
      <ignition_frame_id>camera</ignition_frame_id>
      <pose>0 0 0 0 0 0</pose>
      <topic>/image_raw</topic>
      <camera name="my_camera">
        <horizontal_fov>1.3962634</horizontal_fov>
        <image>
           <width>600</width>
           <height>600</height>
           <format>R8G8B8</format>
        </image>
        <clip>
          <near>0.02</near>
          <far>300</far>
        </clip>
      </camera>
    </sensor>
  </gazebo>

  <!-- 深度相机 -->

  <gazebo reference="camera">
    <sensor name="depth_camera" type="depth_camera">
          <update_rate>10</update_rate>
          <topic>depth_camera</topic>
          <camera>
            <horizontal_fov>1.05</horizontal_fov>
            <image>
              <width>256</width>
              <height>256</height>
              <format>R_FLOAT32</format>
            </image>
            <clip>
              <near>0.1</near>
              <far>10.0</far>
            </clip>
          </camera>
          <alwaysOn>1</alwaysOn>
          <ignition_frame_id>base_link</ignition_frame_id>
      </sensor>
  </gazebo>


</robot>