<?xml version="1.0" encoding="utf-8"?>
<robot
  name="CyberNaviRobot">
  <link
    name="base_link">
    <inertial>
      <origin
        xyz="-0.0126930979005275 0.00191328701604972 0.138027242309266"
        rpy="0 0 0" />
      <mass
        value="1.02316767990512" />
      <inertia
        ixx="0.00139586884914313"
        ixy="-1.1634425915606E-06"
        ixz="2.08900696909113E-08"
        iyy="0.00163816424060367"
        iyz="1.3906877128818E-07"
        izz="0.00212627787861002" />
    </inertial>
    <visual>
      <origin
        xyz="0 0 0"
        rpy="0 0 0" />
      <geometry>
        <mesh
          filename="package://cpp01_urdf/meshes/base_link.STL" />
      </geometry>
      <material
        name="">
        <color
          rgba="1 1 1 1" />
      </material>
    </visual>
    <collision>
      <origin
        xyz="0 0 0"
        rpy="0 0 0" />
      <geometry>
        <mesh
          filename="package://cpp01_urdf/meshes/base_link.STL" />
      </geometry>
    </collision>
  </link>
  <link
    name="left_front_wheel_link">
    <inertial>
      <origin
        xyz="-3.0979511909876E-06 0.0173322020637727 4.43766253017258E-06"
        rpy="0 0 0" />
      <mass
        value="0.0503853041294886" />
      <inertia
        ixx="5.77203859894131E-06"
        ixy="-6.39490308551869E-10"
        ixz="-6.55101507497994E-10"
        iyy="7.74120907350755E-06"
        iyz="1.14467480632514E-09"
        izz="5.77288622221224E-06" />
    </inertial>
    <visual>
      <origin
        xyz="0 0 0"
        rpy="0 0 0" />
      <geometry>
        <mesh
          filename="package://cpp01_urdf/meshes/left_front_wheel_link.STL" />
      </geometry>
      <material
        name="">
        <color
          rgba="1 1 1 1" />
      </material>
    </visual>
    <collision>
      <origin
        xyz="0 0 0"
        rpy="0 0 0" />
      <geometry>
        <mesh
          filename="package://cpp01_urdf/meshes/left_front_wheel_link.STL" />
      </geometry>
    </collision>
  </link>
  <joint
    name="left_front_wheel_joint"
    type="continuous">
    <origin
      xyz="0.094976 0.076703 0.038001"
      rpy="0 0 0" />
    <parent
      link="base_link" />
    <child
      link="left_front_wheel_link" />
    <axis
      xyz="0 1 0" />
  </joint>
  <link
    name="left_rear_wheel_link">
    <inertial>
      <origin
        xyz="-3.06188346035907E-06 0.017331873242395 -5.84140984641324E-06"
        rpy="0 0 0" />
      <mass
        value="0.0503852022031433" />
      <inertia
        ixx="5.7719914844331E-06"
        ixy="-6.47591418647473E-10"
        ixz="6.3996728285628E-10"
        iyy="7.74122667602425E-06"
        iyz="-1.13209672720901E-09"
        izz="5.77285855433357E-06" />
    </inertial>
    <visual>
      <origin
        xyz="0 0 0"
        rpy="0 0 0" />
      <geometry>
        <mesh
          filename="package://cpp01_urdf/meshes/left_rear_wheel_link.STL" />
      </geometry>
      <material
        name="">
        <color
          rgba="1 1 1 1" />
      </material>
    </visual>
    <collision>
      <origin
        xyz="0 0 0"
        rpy="0 0 0" />
      <geometry>
        <mesh
          filename="package://cpp01_urdf/meshes/left_rear_wheel_link.STL" />
      </geometry>
    </collision>
  </link>
  <joint
    name="left_rear_wheel_joint"
    type="continuous">
    <origin
      xyz="-0.078024 0.076703 0.038001"
      rpy="0 0 0" />
    <parent
      link="base_link" />
    <child
      link="left_rear_wheel_link" />
    <axis
      xyz="0 1 0" />
  </joint>
  <link
    name="right_front_wheel_link">
    <inertial>
      <origin
        xyz="3.06240360546661E-06 -0.0173318735620233 -5.84117647387666E-06"
        rpy="0 0 0" />
      <mass
        value="0.0503852021760132" />
      <inertia
        ixx="5.77199099297903E-06"
        ixy="-6.47832070333766E-10"
        ixz="-6.39570296767498E-10"
        iyy="7.74122684098967E-06"
        iyz="1.13229861557678E-09"
        izz="5.7728593340892E-06" />
    </inertial>
    <visual>
      <origin
        xyz="0 0 0"
        rpy="0 0 0" />
      <geometry>
        <mesh
          filename="package://cpp01_urdf/meshes/right_front_wheel_link.STL" />
      </geometry>
      <material
        name="">
        <color
          rgba="1 1 1 1" />
      </material>
    </visual>
    <collision>
      <origin
        xyz="0 0 0"
        rpy="0 0 0" />
      <geometry>
        <mesh
          filename="package://cpp01_urdf/meshes/right_front_wheel_link.STL" />
      </geometry>
    </collision>
  </link>
  <joint
    name="right_front_wheel_joint"
    type="continuous">
    <origin
      xyz="0.094976 -0.075297 0.038001"
      rpy="0 0 0" />
    <parent
      link="base_link" />
    <child
      link="right_front_wheel_link" />
    <axis
      xyz="0 1 0" />
  </joint>
  <link
    name="right_rear_wheel_link">
    <inertial>
      <origin
        xyz="3.09795119093903E-06 -0.0173322020637727 4.43766253057504E-06"
        rpy="0 0 0" />
      <mass
        value="0.0503853041294886" />
      <inertia
        ixx="5.77203859894127E-06"
        ixy="-6.39490308545873E-10"
        ixz="6.55101507484353E-10"
        iyy="7.7412090735075E-06"
        iyz="-1.14467480634659E-09"
        izz="5.77288622221223E-06" />
    </inertial>
    <visual>
      <origin
        xyz="0 0 0"
        rpy="0 0 0" />
      <geometry>
        <mesh
          filename="package://cpp01_urdf/meshes/right_rear_wheel_link.STL" />
      </geometry>
      <material
        name="">
        <color
          rgba="1 1 1 1" />
      </material>
    </visual>
    <collision>
      <origin
        xyz="0 0 0"
        rpy="0 0 0" />
      <geometry>
        <mesh
          filename="package://cpp01_urdf/meshes/right_rear_wheel_link.STL" />
      </geometry>
    </collision>
  </link>
  <joint
    name="right_rear_wheel_joint"
    type="continuous">
    <origin
      xyz="-0.078024 -0.075297 0.038001"
      rpy="0 0 0" />
    <parent
      link="base_link" />
    <child
      link="right_rear_wheel_link" />
    <axis
      xyz="0 1 0" />
  </joint>
</robot>