<?xml version="1.0"?>
<robot name="fishbot">


  <!-- Robot Footprint -->
  <link name="base_footprint"/>

  <joint name="base_joint" type="fixed">
    <parent link="base_footprint"/>
    <child link="base_link"/>
    <origin xyz="0.0 0.0 0.076" rpy="0 0 0"/>
  </joint>


  <!-- base link -->
  <link name="base_link">
  	<visual>
      <origin xyz="0 0 0.0" rpy="0 0 0"/>
      <geometry>
		<cylinder length="0.12" radius="0.10"/>
      </geometry>
      <material name="blue">
      	<color rgba="0.1 0.1 1.0 0.5" /> 
      </material>
    </visual>
    <collision>
      <origin xyz="0 0 0.0" rpy="0 0 0"/>
      <geometry>
		<cylinder length="0.12" radius="0.10"/>
      </geometry>
      <material name="blue">
      	<color rgba="0.1 0.1 1.0 0.5" /> 
      </material>
    </collision>
    <inertial>
      <mass value="0.2"/>
      <inertia ixx="0.0122666" ixy="0" ixz="0" iyy="0.0122666" iyz="0" izz="0.02"/>
    </inertial>
  </link>
    
  <!-- laser link -->
  <link name="laser_link">
    <visual>
      <origin xyz="0 0 0" rpy="0 0 0"/>
      <geometry>
        <cylinder length="0.02" radius="0.02"/>
      </geometry>
      <material name="black">
        <color rgba="0.0 0.0 0.0 0.5" /> 
      </material>
    </visual>
    <collision>
      <origin xyz="0 0 0" rpy="0 0 0"/>
      <geometry>
        <cylinder length="0.02" radius="0.02"/>
      </geometry>
      <material name="black">
        <color rgba="0.0 0.0 0.0 0.5" /> 
      </material>
    </collision>
    <inertial>
    <mass value="0.1"/>
      <inertia ixx="0.000190416666667" ixy="0" ixz="0" iyy="0.0001904" iyz="0" izz="0.00036"/>
    </inertial>
  </link>
  
  <!-- laser joint -->
  <joint name="laser_joint" type="fixed">
      <parent link="base_link" />
      <child link="laser_link" />
      <origin xyz="0 0 0.075" />
  </joint>

  <link name="imu_link">
  	<visual>
      <origin xyz="0 0 0.0" rpy="0 0 0"/>
      <geometry>
		    <box size="0.02 0.02 0.02"/>
      </geometry>
    </visual>
    <collision>
      <origin xyz="0 0 0.0" rpy="0 0 0"/>
      <geometry>
		    <box size="0.02 0.02 0.02"/>
      </geometry>
    </collision>
    <inertial>
      <mass value="0.1"/>
        <inertia ixx="0.000190416666667" ixy="0" ixz="0" iyy="0.0001904" iyz="0" izz="0.00036"/>
      </inertial>
  </link>

  <!-- imu joint -->
  <joint name="imu_joint" type="fixed">
      <parent link="base_link" />
      <child link="imu_link" />
      <origin xyz="0 0 0.02" />
  </joint>


  <link name="left_wheel_link">
      <visual>
        <origin xyz="0 0 0" rpy="1.57079 0 0"/>
        <geometry>
          <cylinder length="0.04" radius="0.032"/>
        </geometry>
          <material name="black">
            <color rgba="0.0 0.0 0.0 0.5" /> 
          </material>
      </visual>
      <collision>
        <origin xyz="0 0 0" rpy="1.57079 0 0"/>
        <geometry>
          <cylinder length="0.04" radius="0.032"/>
        </geometry>
          <material name="black">
            <color rgba="0.0 0.0 0.0 0.5" /> 
          </material>
      </collision>
      <inertial>
        <mass value="0.2"/>
          <inertia ixx="0.000190416666667" ixy="0" ixz="0" iyy="0.0001904" iyz="0" izz="0.00036"/>
        </inertial>
  </link>
    
  <link name="right_wheel_link">
      <visual>
        <origin xyz="0 0 0" rpy="1.57079 0 0"/>
        <geometry>
          <cylinder length="0.04" radius="0.032"/>
        </geometry>
          <material name="black">
            <color rgba="0.0 0.0 0.0 0.5" /> 
          </material>
      </visual>
      <collision>
        <origin xyz="0 0 0" rpy="1.57079 0 0"/>
        <geometry>
          <cylinder length="0.04" radius="0.032"/>
        </geometry>
          <material name="black">
            <color rgba="0.0 0.0 0.0 0.5" /> 
          </material>
      </collision>
      <inertial>
      <mass value="0.2"/>
      <inertia ixx="0.000190416666667" ixy="0" ixz="0" iyy="0.0001904" iyz="0" izz="0.00036"/>
    </inertial>
  </link>
    
  <joint name="left_wheel_joint" type="continuous">
      <parent link="base_link" />
      <child link="left_wheel_link" />
      <origin xyz="-0.02 0.10 -0.06" />
      <axis xyz="0 1 0" />
  </joint>

  <joint name="right_wheel_joint" type="continuous">
      <parent link="base_link" />
      <child link="right_wheel_link" />
      <origin xyz="-0.02 -0.10 -0.06" />
      <axis xyz="0 1 0" />
  </joint>

  <link name="caster_link">
      <visual>
        <origin xyz="0 0 0" rpy="1.57079 0 0"/>
        <geometry>
            <sphere radius="0.016"/>
        </geometry>
          <material name="black">
            <color rgba="0.0 0.0 0.0 0.5" /> 
          </material>
      </visual>
      <collision>
        <origin xyz="0 0 0" rpy="1.57079 0 0"/>
        <geometry>
            <sphere radius="0.016"/>
        </geometry>
          <material name="black">
            <color rgba="0.0 0.0 0.0 0.5" /> 
          </material>
      </collision>
      <inertial>
      <mass value="0.02"/>
      <inertia ixx="0.000190416666667" ixy="0" ixz="0" iyy="0.0001904" iyz="0" izz="0.00036"/>
    </inertial>
  </link>
    
  <joint name="caster_joint" type="fixed">
      <parent link="base_link" />
      <child link="caster_link" />
      <origin xyz="0.06 0.0 -0.076" />
      <axis xyz="0 1 0" />
  </joint>



  <gazebo reference="caster_link">
    <material>Gazebo/Black</material>
  </gazebo>

  <gazebo reference="caster_link">
    <mu1 value="0.0"/>
    <mu2 value="0.0"/>
    <kp value="1000000.0" />
    <kd value="10.0" />
  </gazebo>

</robot>